Workbook

Sheet 00_Notice
A1: REFERENTIEL URIE v1 : taxonomie des compétences et des erreurs
A2: Mathématiques, 6ème à Terminale D, programme burkinabè, Hakili Lab
A3: Version 1.0 du 12 octobre 2026, alignée sur la batterie de tests allégée du 6 octobre 2026. A VALIDER par un enseignant de mathématiques avant figeage.
A5: Ce qui change par rapport à la v0
A6: La v0 (28 juillet 2026) taguait la première batterie : 7 tests de 40 questions, sans partie C. Cette batterie n'existe plus, et les mêmes codes désignent aujourd'hui d'autres questions (en 6ème, G2 était un angle de 47°, c'est aujourd'hui une question de perpendicularité). Une copie corrigée avec la v0 serait créditée à la mauvaise compétence, sans aucun message d'erreur : la v0 ne doit plus servir.
A7: Onglets 04 à 06 refaits sur les sujets actuels : 282 questions (124 en partie A 86 en partie B 72 sous-questions en partie C) 1 041 erreurs attendues 172 options de QCM.
A8: La partie C est taguée sous-question par sous-question (P1.1, P1.2, P1.3...) : chaque problème croise 2 à 6 compétences, une ligne par problème ne dirait pas laquelle a manqué. Le barème de chaque sous-question est celui du corrigé.
A9: Onglet 03 : la colonne Groupe (allocation de l'ancienne batterie de 40 questions) est retirée ; les nombres attendus sont ceux des matrices actuelles.
A10: Onglet 07 : contrôle par compétence (A, B, C) et contrôle par test (barème, couverture de la partie C).
A11: Nouvel onglet 09 : incohérences relevées dans les sujets, les corrigés, les matrices et le pont pendant le tagage, classées par priorité.
A12: Onglets 01, 02 et 08 inchangés : la liste des compétences de chaque test n'a pas changé depuis le 27 juillet.
A14: Le principe : un problème = une compétence x un type d'erreur
... A46: A arbitrer : les 5 anomalies de priorité 1 de l'onglet 09, avant la prochaine passation.

Sheet 01_Types_erreur
A1: Code | B1: Type d'erreur | C1: Definition | D1: Signature observable sur la copie | E1: Exemple concret | F1: Coefficient de cout | G1: Donne lieu a remediation
A2: PRQ | B2: Prerequis manquant | C2: L'echec ne porte pas sur la competence visee mais sur un acquis d'une classe anterieure que cette competence mobilise. | D2: Echec correle sur plusieurs competences differentes qui partagent le meme prerequis. Se lit sur le PROFIL, jamais sur une question isolee. | E2: Echec sur l'equation x/3 - 2 = x/6 + 1 cause par l'incapacite a additionner deux fractions, et non par la resolution d'equation. | F2: 0.5 | G2: OUI
A3: CPT | B3: Erreur conceptuelle | C3: Une notion est comprise de travers : confusion entre deux objets, ou regle fausse appliquee de facon systematique et coherente. | D3: Erreur reproductible sur tous les questions de la meme competence, logique du point de vue de l'eleve. Resiste a la simple repetition. | E3: Reponse 4x^2 + 9 au developpement de (2x-3)^2 : l'eleve croit que le carre se distribue sur une somme. | F3: 0.35 | G3: OUI
A4: MOD | B4: Erreur de modelisation | C4: L'eleve maitrise la technique mais ne traduit pas l'enonce en objet mathematique. | D4: Reussite en partie A sur la competence, echec en partie B sur la meme competence en situation. | E4: Sur 'Karim achete 5 poulets et un sac de riz a 9000 F, il paie 24000 F', ecrire 5(x + 9000) = 24000 au lieu de 5x + 9000 = 24000. | F4: 0.25 | G4: OUI
A5: PRC | B5: Erreur procedurale | C5: La regle est connue et correctement choisie, mais son execution echoue. | D5: Demarche juste et lisible, resultat faux. Souvent signe, retenue, ou etape omise. | E5: Mise au meme denominateur correcte dans -3/4 + 5/6 puis erreur de signe au numerateur. | F5: 0.15 | G5: OUI
A6: CNS | B6: Connaissance non disponible | C6: La formule, la definition ou la propriete n'est pas mobilisee. | D6: Absence de reponse, ou formule enoncee de facon fausse mais assumee. | E6: Volume du cone calcule par pi*r^2*h : la formule est connue pour le cylindre, pas pour le cone. | F6: 0.1 | G6: OUI
A7: RED | B7: Defaut de redaction ou de justification | C7: Le resultat est juste mais la demarche n'est pas justifiee, ou la redaction ne permet pas de la suivre. | D7: Uniquement en partie B, ou la consigne precise que la demarche est evaluee autant que le resultat. | E7: MF = 4,5 cm donne sans citer le theoreme des milieux ni poser le raisonnement. | F7: 0.15 | G7: OUI
A8: ATT | B8: Inattention | C8: Erreur ponctuelle, non reproductible, sans logique sous-jacente. | D8: Une seule question echoue alors que les autres questions de la meme competence sont reussis. Doit etre ECARTE au test de confirmation, jamais remedie. | E8: Recopie 5x - 7 = 2x + 8 en 5x - 7 = 2x + 3 puis resolution parfaitement correcte. | F8: 0 | G8: NON

Sheet 02_Competences
A1: Code canonique | B1: Domaine | C1: Libelle | D1: Description | E1: Niveau d'introduction | F1: Chapitre d'origine | G1: Transversale | H1: Prerequis directs | I1: Volume horaire officiel | J1: Source du volume
A2: N.NUM | B2: Activites numeriques | C2: Numeration decimale | D2: Lire, ecrire, decomposer un entier ou un decimal ; valeur de position d'un chiffre. | E2: Primaire | F2: CE2-CM2 / 6e ch2 | G2: OUI | I2: 2 | J2: curriculum ou guide de l'enseignant
A3: N.CMP | B3: Activites numeriques | C3: Comparaison et rangement | D3: Comparer, ranger et encadrer des entiers et des decimaux. | E3: Primaire | F3: CM1-CM2 / 6e ch7 | G3: OUI | H3: N.NUM | I3: 3 | J3: curriculum ou guide de l'enseignant
A4: N.ADD | B4: Activites numeriques | C4: Addition et soustraction | D4: Addition et soustraction d'entiers et de decimaux, technique et sens. | E4: Primaire | F4: CE1-CM1 / 6e ch4 | G4: OUI | H4: N.NUM | I4: 1.5 | J4: curriculum ou guide de l'enseignant
A5: N.MUL | B5: Activites numeriques | C5: Multiplication | D5: Multiplication d'entiers et de decimaux, technique et sens. | E5: Primaire | F5: CM1-CM2 / 6e ch4 | G5: OUI | H5: N.NUM | I5: 1.5 | J5: curriculum ou guide de l'enseignant
A6: N.DIVE | B6: Activites numeriques | C6: Division euclidienne et decimale | D6: Quotient et reste ; division decimale ; sens de la division. | E6: Primaire | F6: CM1-CM2 / 6e ch4 | G6: OUI | H6: N.MUL | I6: 1.5 | J6: curriculum ou guide de l'enseignant
A7: N.PRIO | B7: Activites numeriques | C7: Priorites operatoires | D7: Regles de priorite, parentheses, proprietes des operations. | E7: 6eme | F7: 6e ch4 | G7: OUI | H7: N.ADD ; N.MUL | I7: 1.5 | J7: curriculum ou guide de l'enseignant
A8: N.AST | B8: Activites numeriques | C8: Calcul astucieux | D8: Mobiliser les proprietes des operations pour simplifier un calcul. | E8: 6eme | F8: 6e ch4 | G8: non | H8: N.PRIO | I8: 1.5 | J8: curriculum ou guide de l'enseignant
A9: N.PROB | B9: Activites numeriques | C9: Choix de l'operation | D9: Choisir la bonne operation dans un probleme a une ou deux etapes. | E9: Primaire | F9: CM1-CM2 | G9: OUI | H9: N.ADD ; N.MUL ; N.DIVE | I9: 4 | J9: estimation (acquis du primaire, non chiffre)
A10: N.FRA1 | B10: Activites numeriques | C10: Fractions : sens et comparaison | D10: Sens de la fraction, fraction d'une quantite, simplification, comparaison. | E10: Primaire | F10: CM1-CM2 / 6e ch12 | G10: OUI | H10: N.DIVE | I10: 8 | J10: curriculum ou guide de l'enseignant
A11: N.EGT | B11: Activites numeriques | C11: Egalites a trous | D11: Determiner le terme manquant dans une egalite numerique. | E11: 6eme | F11: 6e ch13 | G11: non | H11: N.ADD ; N.MUL | I11: 2 | J11: curriculum ou guide de l'enseignant
A12: N.REL | B12: Activites numeriques | C12: Nombres relatifs : reperage | D12: Reperage, comparaison et rangement des nombres relatifs. | E12: 6eme | F12: 6e ch14 | G12: OUI | H12: N.CMP | I12: 5 | J12: curriculum ou guide de l'enseignant
A13: N.RELOP | B13: Activites numeriques | C13: Operations sur les relatifs | D13: Addition et soustraction dans D ; regle des signes. | E13: 5eme | F13: 5e ch7 | G13: OUI | H13: N.REL ; N.ADD | I13: 7 | J13: curriculum ou guide de l'enseignant
A14: N.DIVIS | B14: Activites numeriques | C14: Multiples, diviseurs, premiers | D14: Criteres de divisibilite, multiples, diviseurs, nombres premiers. | E14: 5eme | F14: 5e ch2 | G14: non | H14: N.DIVE | I14: 8 | J14: curriculum ou guide de l'enseignant
... A25: N.INT | B25: Activites numeriques | C25: Intervalles et distance | D25: Intervalles, encadrement, valeur absolue et distance sur une droite. | E25: 3eme | F25: 3e ch1 | G25: non | H25: N.VAB ; N.APP | I25: 7 | J25: curriculum ou guide de l'enseignant
A26: N.MAJ | B26: Activites numeriques | C26: Majorant, minorant | D26: Majorant, minorant, bornes d'un ensemble ou d'un intervalle. | E26: 2ndeC | F26: 2nde ch1 | G26: non | H26: N.INT | I26: non disponible | J26: lycee : pas de volume par chapitre dans les documents officiels
A27: L.EGA | B27: Calcul litteral et algebre | C27: Egalites et transformations | D27: Regles de transformation d'une egalite (ajouter, multiplier des deux cotes). | E27: 5eme | F27: 5e ch13 | G27: OUI | H27: N.PRIO | I27: 2 | J27: curriculum ou guide de l'enseignant
A28: L.EQD | B28: Calcul litteral et algebre | C28: Equations dans D | D28: Resoudre une equation du premier degre a coefficients decimaux. | E28: 5eme | F28: 5e ch14 | G28: non | H28: L.EGA | I28: 4 | J28: curriculum ou guide de l'enseignant
A29: L.DEV1 | B29: Calcul litteral et algebre | C29: Developpement et reduction | D29: Distributivite simple et double ; reduction d'une expression litterale. | E29: 5eme | F29: 5e ch10 / 4e ch15 | G29: OUI | H29: N.MULD ; N.RELOP | I29: 4.5 | J29: curriculum ou guide de l'enseignant
A30: L.FAC1 | B30: Calcul litteral et algebre | C30: Factorisation par facteur commun | D30: Reconnaitre et mettre en evidence un facteur commun. | E30: 4eme | F30: 4e ch15 | G30: OUI | H30: L.DEV1 | I30: 2 | J30: curriculum ou guide de l'enseignant
A31: L.IDR | B31: Calcul litteral et algebre | C31: Identites remarquables : developpement | D31: Developper (a+b)^2, (a-b)^2, (a+b)(a-b). | E31: 4eme | F31: 4e ch15 / 3e ch9 | G31: OUI | H31: L.DEV1 | I31: 2 | J31: curriculum ou guide de l'enseignant
A32: L.FAC2 | B32: Calcul litteral et algebre | C32: Factorisation par identite remarquable | D32: Reconnaitre et factoriser a l'aide d'une identite remarquable. | E32: 3eme | F32: 3e ch9 | G32: OUI | H32: L.IDR ; L.FAC1 | I32: 4 | J32: curriculum ou guide de l'enseignant
A33: L.EQ1 | B33: Calcul litteral et algebre | C33: Equations du premier degre dans R | D33: Resoudre une equation du premier degre, y compris a coefficients fractionnaires. | E33: 4eme | F33: 4e ch16 | G33: OUI | H33: L.EQD ; N.RAT | I33: 1.5 | J33: curriculum ou guide de l'enseignant
A34: L.INEQ1 | B34: Calcul litteral et algebre | C34: Inequations du premier degre | D34: Resoudre et representer les solutions d'une inequation du premier degre. | E34: 4eme | F34: 4e ch16 / 3e ch7 | G34: OUI | H34: L.EQ1 ; N.REL | I34: 1.5 | J34: curriculum ou guide de l'enseignant
A35: L.EQP | B35: Calcul litteral et algebre | C35: Equations produit | D35: Resoudre une equation produit nul apres factorisation. | E35: 3eme | F35: 3e ch7 | G35: non | H35: L.EQ1 ; L.FAC2 | I35: 4 | J35: curriculum ou guide de l'enseignant
A36: L.SYS | B36: Calcul litteral et algebre | C36: Systemes deux equations deux inconnues | D36: Resoudre par substitution ou combinaison ; interpreter. | E36: 3eme | F36: 3e ch15 | G36: non | H36: L.EQ1 | I36: 8 | J36: curriculum ou guide de l'enseignant
A37: L.MISE | B37: Calcul litteral et algebre | C37: Mise en equation d'un probleme | D37: Traduire un enonce en equation ou en inequation d'inconnue choisie. | E37: 4eme | F37: 4e ch16 | G37: OUI | H37: L.EQ1 | I37: 1.5 | J37: curriculum ou guide de l'enseignant
A38: L.EQ2 | B38: Calcul litteral et algebre | C38: Equations du second degre | D38: Discriminant, racines, resolution. | E38: 2ndeC | F38: 2nde ch2 | G38: non | H38: L.EQ1 ; L.FAC2 ; N.RAC | I38: non disponible | J38: lycee : pas de volume par chapitre dans les documents officiels
A39: L.TRI | B39: Calcul litteral et algebre | C39: Trinome : factorisation et signe | D39: Factoriser un trinome et etablir son tableau de signe. | E39: 2ndeC | F39: 2nde ch2 | G39: non | H39: L.EQ2 | I39: non disponible | J39: lycee : pas de volume par chapitre dans les documents officiels
A40: L.INEQ2 | B40: Calcul litteral et algebre | C40: Inequations produit et quotient | D40: Resoudre par tableau de signe une inequation produit ou quotient. | E40: 2ndeC | F40: 2nde ch2 | G40: non | H40: L.TRI ; L.INEQ1 | I40: non disponible | J40: lycee : pas de volume par chapitre dans les documents officiels
A41: L.SYSL | B41: Calcul litteral et algebre | C41: Systemes lineaires et d'inequations | D41: Systemes lineaires, systemes d'inequations a deux inconnues. | E41: 2ndeC | F41: 2nde ch4 | G41: non | H41: L.SYS ; L.INEQ1 | I41: non disponible | J41: lycee : pas de volume par chapitre dans les documents officiels
A42: L.POLY | B42: Calcul litteral et algebre | C42: Polynomes | D42: Factorisation, racines, mise en facteur, division euclidienne. | E42: 1ereD | F42: 1ere ch2 | G42: non | H42: L.TRI | I42: non disponible | J42: lycee : pas de volume par chapitre dans les documents officiels
A43: L.RATF | B43: Calcul litteral et algebre | C43: Fonctions rationnelles : calcul | D43: Simplification, signe et resolution sur les fonctions rationnelles. | E43: 1ereD | F43: 1ere ch2, ch3 | G43: non | H43: L.POLY ; L.INEQ2 | I43: non disponible | J43: lycee : pas de volume par chapitre dans les documents officiels
A44: G.VOC | B44: Activites geometriques | C44: Vocabulaire et traces de base | D44: Droite, demi-droite, segment, milieu : notation et trace. | E44: Primaire | F44: CE2-CM1 / 6e ch1 | G44: OUI | I44: 2 | J44: curriculum ou guide de l'enseignant
A45: G.PARA | B45: Activites geometriques | C45: Parallelisme et perpendicularite | D45: Reconnaitre et tracer des droites paralleles ou perpendiculaires. | E45: Primaire | F45: CM1-CM2 / 6e ch1 | G45: OUI | H45: G.VOC | I45: 2 | J45: curriculum ou guide de l'enseignant
A46: G.FIG | B46: Activites geometriques | C46: Figures usuelles | D46: Reconnaitre et construire carre, rectangle, triangle, cercle. | E46: Primaire | F46: CE2-CM2 | G46: OUI | H46: G.VOC | I46: 4 | J46: estimation (acquis du primaire, non chiffre)
A47: G.ANG1 | B47: Activites geometriques | C47: Angles : nature et mesure | D47: Nature d'un angle, mesure et construction au rapporteur. | E47: Primaire | F47: CM1-CM2 / 6e ch3 | G47: OUI | I47: 2.5 | J47: curriculum ou guide de l'enseignant
A48: G.ANG2 | B48: Activites geometriques | C48: Angles complementaires et bissectrice | D48: Angles complementaires, supplementaires, bissectrice. | E48: 6eme | F48: 6e ch3 | G48: non | H48: G.ANG1 | I48: 2.5 | J48: curriculum ou guide de l'enseignant
A49: G.TRI | B49: Activites geometriques | C49: Triangles : construction et nature | D49: Construction, nature d'un triangle, inegalite triangulaire. | E49: 6eme | F49: 6e ch8 | G49: OUI | H49: G.FIG | I49: 7 | J49: curriculum ou guide de l'enseignant
A50: G.PARAL | B50: Activites geometriques | C50: Parallelogrammes | D50: Parallelogramme et parallelogrammes particuliers : reconnaissance et proprietes. | E50: 6eme | F50: 6e ch5, ch6 | G50: non | H50: G.PARA ; G.FIG | I50: 8.5 | J50: curriculum ou guide de l'enseignant
...

Sheet 03_Pont_tests
A1: Test d'entrée en | B1: Code local (matrice) | C1: Code(s) canonique(s) | D1: Questions attendues en partie A | E1: Questions attendues en partie B | F1: Total attendu A + B
A2: 6eme | B2: N-a | C2: N.NUM | D2: 1 | E2: 0 | F2: 1
A3: 6eme | B3: N-b | C3: N.CMP | D3: 1 | E3: 0 | F3: 1
A4: 6eme | B4: N-c | C4: N.ADD | D4: 1 | E4: 1 | F4: 2
A5: 6eme | B5: N-d | C5: N.MUL | D5: 1 | E5: 1 | F5: 2
A6: 6eme | B6: N-e | C6: N.DIVE | D6: 1 | E6: 1 | F6: 2
A7: 6eme | B7: N-f | C7: N.FRA1 | D7: 1 | E7: 1 | F7: 2
A8: 6eme | B8: N-g | C8: N.PROB | D8: 1 | E8: 1 | F8: 2
A9: 6eme | B9: M-a | C9: M.CONV | D9: 1 | E9: 0 | F9: 1
A10: 6eme | B10: M-b | C10: M.PER | D10: 1 | E10: 1 | F10: 2
A11: 6eme | B11: M-c | C11: M.AIRE | D11: 1 | E11: 1 | F11: 2
A12: 6eme | B12: G-a | C12: G.VOC | D12: 1 | E12: 0 | F12: 1
A13: 6eme | B13: G-b | C13: G.PARA | D13: 1 | E13: 1 | F13: 2
... A117: tleD | B117: G-b | C117: G.ESP | D117: 1 | E117: 1 | F117: 2

Sheet 04_Questions
A1: Niveau du test | B1: Code question | C1: Partie | D1: Barème | E1: Format | F1: Code local | G1: Compétence principale | H1: Compétence secondaire | I1: Objet de la question
A2: 6eme | B2: N1 | C2: A | D2: 1 | E2: court | F2: N-b | G2: N.CMP | I2: Ranger dans l'ordre décroissant 9,08 ; 9,8 ; 9,081 ; 9,1
A3: 6eme | B3: N2 | C3: A | D3: 1 | E3: qcm | F3: N-a | G3: N.NUM | I3: Choisir l'écriture du nombre qui vaut 5 centaines et 9 centièmes
A4: 6eme | B4: N3 | C4: A | D4: 1 | E4: court | F4: N-c | G4: N.ADD | I4: Effectuer la soustraction 14 - 6,75
A5: 6eme | B5: N4 | C5: A | D5: 1 | E5: court | F5: N-d | G5: N.MUL | I5: Effectuer le produit 4,06 × 25
A6: 6eme | B6: N5 | C6: A | D6: 1 | E6: qcm | F6: N-f | G6: N.FRA1 | I6: Choisir la valeur des trois quarts de 60 kg
A7: 6eme | B7: N6 | C7: A | D7: 1 | E7: court | F7: N-e | G7: N.DIVE | I7: Effectuer la division euclidienne de 842 par 25 (quotient et reste)
A8: 6eme | B8: N7 | C8: A | D8: 1 | E8: qcm | F8: N-g | G8: N.PROB | I8: Choisir le calcul de la monnaie : 4 pagnes à 3 500 FCFA payés avec 20 000 FCFA (Rasmané)
A9: 6eme | B9: M1 | C9: A | D9: 1 | E9: court | F9: M-a | G9: M.CONV | I9: Convertir 3,07 m en centimètres
A10: 6eme | B10: M2 | C10: A | D10: 1 | E10: court | F10: M-b | G10: M.PER | H10: N.ADD | I10: Calculer le périmètre d'un triangle de côtés 4,5 cm, 6 cm et 3,8 cm
A11: 6eme | B11: M3 | C11: A | D11: 1 | E11: qcm | F11: M-c | G11: M.AIRE | I11: Choisir l'aire d'un triangle de base 7 cm et de hauteur 4 cm (côté de 5 cm inutile)
A12: 6eme | B12: G1 | C12: A | D12: 1 | E12: court | F12: G-a | G12: G.VOC | I12: Calculer EF sachant que I est le milieu de [EF] et IE = 3,5 cm
A13: 6eme | B13: G2 | C13: A | D13: 1 | E13: court | F13: G-b | G13: G.PARA | I13: Nommer les deux côtés perpendiculaires au côté [AB] dans le carré ABCD
A14: 6eme | B14: G3 | C14: A | D14: 1 | E14: qcm | F14: G-d | G14: G.ANG1 | I14: Choisir la mesure d'un angle obtus lu 40 et 140 au rapporteur (Kadidiatou)
A15: 6eme | B15: G4 | C15: A | D15: 1 | E15: court | F15: G-c | G15: G.FIG | I15: Dire lequel de P (OP = 4,5 cm) ou Q (OQ = 3 cm) est sur le cercle de centre O, rayon 3 cm
A16: 6eme | B16: D1 | C16: A | D16: 1 | E16: court | F16: D-a | G16: D.PROP | I16: Calculer le prix de 7 kg de riz sachant que 4 kg coûtent 2 600 FCFA
A17: 6eme | B17: D2 | C17: A | D17: 1 | E17: qcm | F17: D-b | G17: D.POUR | I17: Choisir le pourcentage d'élèves de CM2 : 50 sur 200 élèves (école de Manga)
A18: 6eme | B18: N8 | C18: B | D18: 2 | E18: rédigé | F18: N-c | G18: N.ADD | I18: Retrouver l'essence au départ : 4,25 L dans le réservoir après ajout de 1,5 L (Salif)
A19: 6eme | B19: N9 | C19: B | D19: 2 | E19: rédigé | F19: N-d | G19: N.MUL | H19: N.PROB | I19: Ecrire en une ligne puis calculer le prix du double de 12 savons à 325 FCFA (Safiatou)
A20: 6eme | B20: N10 | C20: B | D20: 2 | E20: rédigé | F20: N-e | G20: N.DIVE | I20: Juger si 16 plateaux de 30 oeufs suffisent pour 500 oeufs (Nafissatou)
A21: 6eme | B21: N11 | C21: B | D21: 2 | E21: rédigé | F21: N-f | G21: N.FRA1 | I21: Retrouver le grenier plein (le tiers vaut 12 sacs) et juger l'ajout de 30 sacs (Réo)
A22: 6eme | B22: N12 | C22: B | D22: 2 | E22: rédigé | F22: N-g | G22: N.PROB | H22: N.DIVE | I22: Calculer le prix de vente d'un poulet pour gagner 8 000 FCFA sur 8 poulets payés 15 000 FCFA
A23: 6eme | B23: M4 | C23: B | D23: 2 | E23: rédigé | F23: M-b | G23: M.PER | H23: N.DIVE | I23: Calculer la largeur d'un rectangle (périmètre 46 m, longueur 14 m) et les rouleaux de 20 m
A24: 6eme | B24: M5 | C24: B | D24: 2 | E24: rédigé | F24: M-c | G24: M.AIRE | I24: Juger s'il reste plus de 550 m² sur un terrain de 600 m² après un hangar carré de 8 m
A25: 6eme | B25: G5 | C25: B | D25: 2 | E25: rédigé | F25: G-b | G25: G.PARA | H25: G.FIG | I25: Calculer RS dans le rectangle MNPQ (NP = 4 cm) et juger si (RS) et (MQ) sont perpendiculaires
A26: 6eme | B26: G6 | C26: B | D26: 2 | E26: construction | F26: G-c | G26: G.FIG | I26: Calculer le rayon d'un cercle de diamètre 7 cm puis tracer ce cercle au compas
A27: 6eme | B27: G7 | C27: B | D27: 2 | E27: rédigé | F27: G-d | G27: G.ANG1 | I27: Calculer l'angle zOy (xOy = 130°, xOz = 40°) et juger s'il est aigu (Kadidiatou)
A28: 6eme | B28: D3 | C28: B | D28: 2 | E28: rédigé | F28: D-a | G28: D.PROP | H28: N.DIVE | I28: Calculer le nombre de sacs à 8 500 FCFA payés 59 500 FCFA et juger l'affirmation « 8 sacs »
A29: 6eme | B29: P1.1 | C29: C | D29: 2 | E29: rédigé | F29: G-a | G29: G.VOC | H29: N.ADD | I29: Calculer la distance Boromo-Bobo (route de 360 km, Boromo à 180 km) et dire si Boromo est le milieu
A30: 6eme | B30: P1.2 | C30: C | D30: 2 | E30: rédigé | F30: M-a | G30: M.CONV | I30: Calculer l'heure de départ de Boromo : départ 6 h 40, trajet 2 h 30 min, arrêt 25 min
A31: 6eme | B31: P1.3 | C31: C | D31: 3 | E31: rédigé | F31: M-a | G31: M.CONV | H31: N.PROB | I31: Calculer l'arrivée (9 h 35 + 2 h 45 min) et la durée depuis 6 h 40, juger « moins de 6 h »
A32: 6eme | B32: P2.1 | C32: C | D32: 2 | E32: rédigé | F32: N-a | G32: N.NUM | H32: N.ADD | I32: Calculer 3 billets de 10 000, 7 de 1 000 et 5 pièces de 100 FCFA, écrire la somme en lettres
A33: 6eme | B33: P2.2 | C33: C | D33: 2 | E33: rédigé | F33: D-b | G33: D.POUR | H33: N.DIVE | I33: Calculer 20 % de 37 500 FCFA (apport de la mairie au forage de Ziniaré)
A34: 6eme | B34: P2.3 | C34: C | D34: 3 | E34: rédigé | F34: N-g | G34: N.PROB | H34: N.ADD | I34: Comparer 37 500 + 7 500 FCFA au forage de 60 000 FCFA et donner la somme qui manque
A35: 6eme | B35: P3.1 | C35: C | D35: 2 | E35: rédigé | F35: N-e | G35: N.DIVE | H35: M.CONV | I35: Calculer le nombre de sacs de 100 kg pour 2 400 kg de sorgho (Dori-Kaya, 180 km inutile)
A36: 6eme | B36: P3.2 | C36: C | D36: 3 | E36: rédigé | F36: D-a | G36: D.PROP | H36: N.MUL | I36: Calculer le prix de 24 sacs : offre A 1 500 FCFA par sac, offre B 20 000 FCFA plus 600 FCFA par sac
A37: 6eme | B37: P3.3 | C37: C | D37: 3 | E37: rédigé | F37: N-b | G37: N.CMP | H37: N.MUL | I37: Calculer les deux offres pour 10 sacs et juger si l'offre B est toujours la moins chère
A38: 5eme | B38: N1 | C38: A | D38: 1 | E38: court | F38: N-a | G38: N.NUM | I38: Ecrire en chiffres cinq unités et trente-quatre millièmes
A39: 5eme | B39: N2 | C39: A | D39: 1 | E39: court | F39: N-b | G39: N.PRIO | I39: Calculer 30 - 4 × (7 - 5)
A40: 5eme | B40: N3 | C40: A | D40: 1 | E40: court | F40: N-e | G40: N.REL | I40: Ranger dans l'ordre croissant -9 ; +2 ; -3 ; -1
...

Sheet 05_Grille_diagnostic
A1: Niveau du test | B1: Code question | C1: Compétence | D1: Type d'erreur | E1: Ce qu'on lit sur la copie | F1: Lacune révélée
A2: 6eme | B2: N1 | C2: N.CMP | D2: CPT | E2: Ecrit 9,081 ; 9,08 ; 9,8 ; 9,1 | F2: Le nombre le plus long est jugé le plus grand : la partie décimale est lue comme un entier (81 > 8 > 1).
A3: 6eme | B3: N1 | C3: N.CMP | D3: CPT | E3: Ecrit 9,8 ; 9,1 ; 9,08 ; 9,081 | F3: Le nombre qui a le moins de chiffres après la virgule est jugé le plus grand (9,8 et 9,1, puis 9,08, puis 9,081) : règle fausse appliquée de façon cohérente.
A4: 6eme | B4: N1 | C4: N.CMP | D4: CNS | E4: Ecrit 9,08 ; 9,081 ; 9,1 ; 9,8 | F4: Le rangement est juste mais croissant : le sens du mot « décroissant » n'est pas disponible.
A5: 6eme | B5: N2 | C5: N.NUM | D5: CPT | E5: Entoure a) 5,09 | F5: Les rangs de la partie entière et de la partie décimale sont confondus : erreur de notion, reproductible.
A6: 6eme | B6: N2 | C6: N.NUM | D6: CPT | E6: Entoure b) 509 | F6: Le mot « centièmes » est associé à « cent » : la valeur de position des chiffres après la virgule n'est pas comprise.
A7: 6eme | B7: N2 | C7: N.NUM | D7: PRC | E7: Entoure c) 500,9 | F7: Le rang des centièmes est connu mais le zéro de position est oublié à l'écriture : exécution fautive.
A8: 6eme | B8: N3 | C8: N.ADD | D8: CPT | E8: Ecrit 8,75 | F8: Les parties entières sont soustraites (14 - 6 = 8) et la partie décimale recopiée : le décimal n'est pas traité comme un seul nombre.
A9: 6eme | B9: N3 | C9: N.ADD | D9: PRC | E9: Ecrit 8,25 | F9: 14,00 - 6,75 est bien posé mais la dernière retenue n'est pas reportée sur les unités (14 - 6 au lieu de 14 - 7).
A10: 6eme | B10: N3 | C10: N.ADD | D10: ATT | E10: Ecrit 7,43 | F10: 6,75 est recopié 6,57 puis la soustraction 14 - 6,57 est juste : erreur de recopie isolée.
A11: 6eme | B11: N4 | C11: N.MUL | D11: PRC | E11: Ecrit 1 015 | F11: Le produit 406 × 25 = 10 150 est juste mais la virgule est placée à un seul rang au lieu de deux.
A12: 6eme | B12: N4 | C12: N.MUL | D12: CPT | E12: Ecrit 100,150 | F12: Partie entière et partie décimale sont multipliées séparément (4 × 25 = 100 ; 6 × 25 = 150) : le décimal est vu comme deux entiers.
... A1042: tleD | B1042: P4.3 | C1042: G.PS | D1042: RED | E1042: Ecrit « isocèle non rectangle » sans citer AB = AC ni 24 ≠ 0 | F1042: La nature est juste mais elle n'est appuyée sur aucune des deux données.

Sheet 06_Distracteurs
A1: Niveau du test | B1: Code question | C1: Option | D1: Texte de l'option | E1: Bonne réponse | F1: Type d'erreur révélé | G1: Erreur qui conduit à cette option
A2: 6eme | B2: N2 | C2: a | D2: 5,09 | E2: non | F2: CPT | G2: Les 5 centaines sont écrites comme 5 unités : l'ordre des rangs autour de la virgule est confondu.
A3: 6eme | B3: N2 | C3: b | D3: 509 | E3: non | F3: CPT | G3: Les 9 centièmes sont écrits comme 9 unités : « centième » est lu comme « cent » et placé dans la partie entière.
A4: 6eme | B4: N2 | C4: c | D4: 500,9 | E4: non | F4: PRC | G4: Le 9 est placé au premier rang après la virgule : le zéro des dixièmes est oublié, ce qui donne 9 dixièmes.
A5: 6eme | B5: N2 | C5: d | D5: 500,09 | E5: OUI
A6: 6eme | B6: N5 | C6: a | D6: 15 kg | E6: non | F6: PRC | G6: Seul le quart est calculé (60 : 4 = 15) : la multiplication par 3 est omise.
A7: 6eme | B7: N5 | C7: b | D7: 20 kg | E7: non | F7: CPT | G7: Division par le numérateur (60 : 3 = 20) : les rôles du numérateur et du dénominateur sont confondus.
A8: 6eme | B8: N5 | C8: c | D8: 45 kg | E8: OUI
A9: 6eme | B9: N5 | C9: d | D9: 80 kg | E9: non | F9: CPT | G9: La fraction est appliquée à l'envers (60 : 3 × 4 = 80) : l'élève prend les quatre tiers au lieu des trois quarts.
A10: 6eme | B10: N7 | C10: a | D10: (20 000 - 3 500) × 4 | E10: non | F10: MOD | G10: La monnaie d'un seul pagne est calculée puis multipliée par 4, comme si chaque pagne était payé avec un billet de 20 000 FCFA.
A11: 6eme | B11: N7 | C11: b | D11: 20 000 - 4 × 3 500 | E11: OUI
A12: 6eme | B12: N7 | C12: c | D12: 4 × 3 500 - 20 000 | E12: non | F12: CPT | G12: Les termes de la soustraction sont inversés : la soustraction est traitée comme si l'ordre ne comptait pas (le résultat serait négatif).
A13: 6eme | B13: N7 | C13: d | D13: 20 000 - 3 500 + 4 | E13: non | F13: MOD | G13: Le nombre de pagnes est ajouté comme une somme d'argent : la quantité 4 n'est pas traduite en multiplication.
A14: 6eme | B14: M3 | C14: a | D14: 14 cm² | E14: OUI
A15: 6eme | B15: M3 | C15: b | D15: 17,5 cm² | E15: non | F15: CPT | G15: Le côté de 5 cm est pris pour la hauteur (7 × 5 : 2 = 17,5) : la hauteur n'est pas reconnue comme perpendiculaire à la base.
A16: 6eme | B16: M3 | C16: c | D16: 28 cm² | E16: non | F16: CNS | G16: La division par 2 est oubliée (7 × 4 = 28) : la formule de l'aire du rectangle remplace celle du triangle.
A17: 6eme | B17: M3 | C17: d | D17: 16 cm² | E17: non | F17: CPT | G17: Les trois longueurs données sont additionnées (7 + 4 + 5 = 16) : l'aire est confondue avec une somme de longueurs.
A18: 6eme | B18: G3 | C18: a | D18: 40° | E18: non | F18: CNS | G18: La petite lecture est retenue : la définition de l'angle obtus (plus de 90°) n'est pas mobilisée pour choisir la graduation.
A19: 6eme | B19: G3 | C19: b | D19: 140° | E19: OUI
A20: 6eme | B20: G3 | C20: c | D20: 180° | E20: non | F20: CPT | G20: Les deux lectures sont additionnées (40 + 140 = 180) : les deux graduations sont vues comme deux morceaux de l'angle.
A21: 6eme | B21: G3 | C21: d | D21: 100° | E21: non | F21: CPT | G21: La différence des deux lectures est prise (140 - 40 = 100) : la double graduation du rapporteur n'est pas comprise.
A22: 6eme | B22: D2 | C22: a | D22: 50 % | E22: non | F22: CNS | G22: L'effectif 50 est recopié comme pourcentage : la notion de pourcentage (rapport ramené à 100) n'est pas disponible.
A23: 6eme | B23: D2 | C23: b | D23: 4 % | E23: non | F23: CPT | G23: Le rapport est inversé (200 : 50 = 4) : l'effectif total est divisé par la partie.
A24: 6eme | B24: D2 | C24: c | D24: 40 % | E24: non | F24: CPT | G24: Rapport inversé (200 : 50 = 4) puis 4 lu comme 0,4, soit 40 % : erreur de sens du rapport aggravée d'une virgule mal placée.
A25: 6eme | B25: D2 | C25: d | D25: 25 % | E25: OUI
A26: 5eme | B26: N6 | C26: a | D26: 18/24 | E26: non | F26: CNS | G26: Diviser seulement par 2 (36 ÷ 2 = 18, 48 ÷ 2 = 24) et s'arrêter : la fraction irréductible n'est pas connue.
A27: 5eme | B27: N6 | C27: b | D27: 3/4 | E27: OUI
A28: 5eme | B28: N6 | C28: c | D28: 6/8 | E28: non | F28: PRC | G28: Diviser par 6 (36 ÷ 6 = 6, 48 ÷ 6 = 8) sans vérifier qu'il reste le diviseur commun 2.
A29: 5eme | B29: N6 | C29: d | D29: 4/3 | E29: non | F29: CPT | G29: Simplifier par 12 (36 ÷ 12 = 3, 48 ÷ 12 = 4) puis échanger numérateur et dénominateur.
A30: 5eme | B30: M3 | C30: a | D30: 25 cm² | E30: non | F30: CNS | G30: Calculer l'aire d'une seule face, 5 × 5 = 25 : l'aire totale n'est pas connue.
A31: 5eme | B31: M3 | C31: b | D31: 125 cm² | E31: non | F31: CPT | G31: Calculer le volume 5 × 5 × 5 = 125 au lieu de l'aire totale.
A32: 5eme | B32: M3 | C32: c | D32: 30 cm² | E32: non | F32: PRC | G32: Compter les six faces mais prendre 5 pour l'aire d'une face : 6 × 5 = 30 au lieu de 6 × 25.
A33: 5eme | B33: M3 | C33: d | D33: 150 cm² | E33: OUI
A34: 5eme | B34: G4 | C34: a | D34: P est le milieu de [EF] | E34: non | F34: CPT | G34: Confondre la médiatrice avec le milieu du segment.
A35: 5eme | B35: G4 | C35: b | D35: PE = EF | E35: non | F35: CNS | G35: Retenir vaguement une égalité de longueurs sans savoir laquelle : l'équidistance n'est pas connue.
A36: 5eme | B36: G4 | C36: c | D36: PE = PF | E36: OUI
A37: 5eme | B37: G4 | C37: d | D37: (PE) ⊥ (PF) | E37: non | F37: CPT | G37: Transférer la perpendicularité de la médiatrice à [EF] aux droites (PE) et (PF).
A38: 5eme | B38: G5 | C38: a | D38: AB = BC | E38: non | F38: CPT | G38: Attribuer au parallélogramme une propriété du losange (côtés consécutifs égaux).
A39: 5eme | B39: G5 | C39: b | D39: AC = BD | E39: non | F39: CPT | G39: Attribuer au parallélogramme une propriété du rectangle (diagonales de même longueur).
A40: 5eme | B40: G5 | C40: c | D40: (AB) ⊥ (BC) | E40: non | F40: CPT | G40: Imaginer le parallélogramme rectangle et lui attribuer un angle droit.
...

Sheet 07_Couverture
A1: Niveau du test | B1: Code local | C1: Compétence(s) canonique(s) | D1: Attendu en A | E1: Tagué en A | F1: Attendu en B | G1: Tagué en B | H1: Sous-questions de C (compétence principale) | I1: Contrôle A et B | J1: Niveau 1 et niveau 2 évalués | K1: Arbitrage documenté
A2: 6eme | B2: N-a | C2: N.NUM | D2: 1 | E2: =COUNTIFS('04_Questions'!$A:$A,$A2,'04_Questions'!$F:$F,$B2,'04_Questions'!$C:$C,"A") | F2: 0 | G2: =COUNTIFS('04_Questions'!$A:$A,$A2,'04_Questions'!$F:$F,$B2,'04_Questions'!$C:$C,"B") | H2: =COUNTIFS('04_Questions'!$A:$A,$A2,'04_Questions'!$F:$F,$B2,'04_Questions'!$C:$C,"C") | I2: =IF(AND(E2=D2,G2=F2),"OK","écart") | J2: =IF(E2>=1,IF(G2+H2>=1,"OK","sans niveau 2"),IF(G2+H2>=1,"sans niveau 1","non évaluée"))
A3: 6eme | B3: N-b | C3: N.CMP | D3: 1 | E3: =COUNTIFS('04_Questions'!$A:$A,$A3,'04_Questions'!$F:$F,$B3,'04_Questions'!$C:$C,"A") | F3: 0 | G3: =COUNTIFS('04_Questions'!$A:$A,$A3,'04_Questions'!$F:$F,$B3,'04_Questions'!$C:$C,"B") | H3: =COUNTIFS('04_Questions'!$A:$A,$A3,'04_Questions'!$F:$F,$B3,'04_Questions'!$C:$C,"C") | I3: =IF(AND(E3=D3,G3=F3),"OK","écart") | J3: =IF(E3>=1,IF(G3+H3>=1,"OK","sans niveau 2"),IF(G3+H3>=1,"sans niveau 1","non évaluée"))
A4: 6eme | B4: N-c | C4: N.ADD | D4: 1 | E4: =COUNTIFS('04_Questions'!$A:$A,$A4,'04_Questions'!$F:$F,$B4,'04_Questions'!$C:$C,"A") | F4: 1 | G4: =COUNTIFS('04_Questions'!$A:$A,$A4,'04_Questions'!$F:$F,$B4,'04_Questions'!$C:$C,"B") | H4: =COUNTIFS('04_Questions'!$A:$A,$A4,'04_Questions'!$F:$F,$B4,'04_Questions'!$C:$C,"C") | I4: =IF(AND(E4=D4,G4=F4),"OK","écart") | J4: =IF(E4>=1,IF(G4+H4>=1,"OK","sans niveau 2"),IF(G4+H4>=1,"sans niveau 1","non évaluée"))
A5: 6eme | B5: N-d | C5: N.MUL | D5: 1 | E5: =COUNTIFS('04_Questions'!$A:$A,$A5,'04_Questions'!$F:$F,$B5,'04_Questions'!$C:$C,"A") | F5: 1 | G5: =COUNTIFS('04_Questions'!$A:$A,$A5,'04_Questions'!$F:$F,$B5,'04_Questions'!$C:$C,"B") | H5: =COUNTIFS('04_Questions'!$A:$A,$A5,'04_Questions'!$F:$F,$B5,'04_Questions'!$C:$C,"C") | I5: =IF(AND(E5=D5,G5=F5),"OK","écart") | J5: =IF(E5>=1,IF(G5+H5>=1,"OK","sans niveau 2"),IF(G5+H5>=1,"sans niveau 1","non évaluée"))
A6: 6eme | B6: N-e | C6: N.DIVE | D6: 1 | E6: =COUNTIFS('04_Questions'!$A:$A,$A6,'04_Questions'!$F:$F,$B6,'04_Questions'!$C:$C,"A") | F6: 1 | G6: =COUNTIFS('04_Questions'!$A:$A,$A6,'04_Questions'!$F:$F,$B6,'04_Questions'!$C:$C,"B") | H6: =COUNTIFS('04_Questions'!$A:$A,$A6,'04_Questions'!$F:$F,$B6,'04_Questions'!$C:$C,"C") | I6: =IF(AND(E6=D6,G6=F6),"OK","écart") | J6: =IF(E6>=1,IF(G6+H6>=1,"OK","sans niveau 2"),IF(G6+H6>=1,"sans niveau 1","non évaluée"))
A7: 6eme | B7: N-f | C7: N.FRA1 | D7: 1 | E7: =COUNTIFS('04_Questions'!$A:$A,$A7,'04_Questions'!$F:$F,$B7,'04_Questions'!$C:$C,"A") | F7: 1 | G7: =COUNTIFS('04_Questions'!$A:$A,$A7,'04_Questions'!$F:$F,$B7,'04_Questions'!$C:$C,"B") | H7: =COUNTIFS('04_Questions'!$A:$A,$A7,'04_Questions'!$F:$F,$B7,'04_Questions'!$C:$C,"C") | I7: =IF(AND(E7=D7,G7=F7),"OK","écart") | J7: =IF(E7>=1,IF(G7+H7>=1,"OK","sans niveau 2"),IF(G7+H7>=1,"sans niveau 1","non évaluée"))
A8: 6eme | B8: N-g | C8: N.PROB | D8: 1 | E8: =COUNTIFS('04_Questions'!$A:$A,$A8,'04_Questions'!$F:$F,$B8,'04_Questions'!$C:$C,"A") | F8: 1 | G8: =COUNTIFS('04_Questions'!$A:$A,$A8,'04_Questions'!$F:$F,$B8,'04_Questions'!$C:$C,"B") | H8: =COUNTIFS('04_Questions'!$A:$A,$A8,'04_Questions'!$F:$F,$B8,'04_Questions'!$C:$C,"C") | I8: =IF(AND(E8=D8,G8=F8),"OK","écart") | J8: =IF(E8>=1,IF(G8+H8>=1,"OK","sans niveau 2"),IF(G8+H8>=1,"sans niveau 1","non évaluée"))
A9: 6eme | B9: M-a | C9: M.CONV | D9: 1 | E9: =COUNTIFS('04_Questions'!$A:$A,$A9,'04_Questions'!$F:$F,$B9,'04_Questions'!$C:$C,"A") | F9: 0 | G9: =COUNTIFS('04_Questions'!$A:$A,$A9,'04_Questions'!$F:$F,$B9,'04_Questions'!$C:$C,"B") | H9: =COUNTIFS('04_Questions'!$A:$A,$A9,'04_Questions'!$F:$F,$B9,'04_Questions'!$C:$C,"C") | I9: =IF(AND(E9=D9,G9=F9),"OK","écart") | J9: =IF(E9>=1,IF(G9+H9>=1,"OK","sans niveau 2"),IF(G9+H9>=1,"sans niveau 1","non évaluée"))
A10: 6eme | B10: M-b | C10: M.PER | D10: 1 | E10: =COUNTIFS('04_Questions'!$A:$A,$A10,'04_Questions'!$F:$F,$B10,'04_Questions'!$C:$C,"A") | F10: 1 | G10: =COUNTIFS('04_Questions'!$A:$A,$A10,'04_Questions'!$F:$F,$B10,'04_Questions'!$C:$C,"B") | H10: =COUNTIFS('04_Questions'!$A:$A,$A10,'04_Questions'!$F:$F,$B10,'04_Questions'!$C:$C,"C") | I10: =IF(AND(E10=D10,G10=F10),"OK","écart") | J10: =IF(E10>=1,IF(G10+H10>=1,"OK","sans niveau 2"),IF(G10+H10>=1,"sans niveau 1","non évaluée"))
A11: 6eme | B11: M-c | C11: M.AIRE | D11: 1 | E11: =COUNTIFS('04_Questions'!$A:$A,$A11,'04_Questions'!$F:$F,$B11,'04_Questions'!$C:$C,"A") | F11: 1 | G11: =COUNTIFS('04_Questions'!$A:$A,$A11,'04_Questions'!$F:$F,$B11,'04_Questions'!$C:$C,"B") | H11: =COUNTIFS('04_Questions'!$A:$A,$A11,'04_Questions'!$F:$F,$B11,'04_Questions'!$C:$C,"C") | I11: =IF(AND(E11=D11,G11=F11),"OK","écart") | J11: =IF(E11>=1,IF(G11+H11>=1,"OK","sans niveau 2"),IF(G11+H11>=1,"sans niveau 1","non évaluée"))
A12: 6eme | B12: G-a | C12: G.VOC | D12: 1 | E12: =COUNTIFS('04_Questions'!$A:$A,$A12,'04_Questions'!$F:$F,$B12,'04_Questions'!$C:$C,"A") | F12: 0 | G12: =COUNTIFS('04_Questions'!$A:$A,$A12,'04_Questions'!$F:$F,$B12,'04_Questions'!$C:$C,"B") | H12: =COUNTIFS('04_Questions'!$A:$A,$A12,'04_Questions'!$F:$F,$B12,'04_Questions'!$C:$C,"C") | I12: =IF(AND(E12=D12,G12=F12),"OK","écart") | J12: =IF(E12>=1,IF(G12+H12>=1,"OK","sans niveau 2"),IF(G12+H12>=1,"sans niveau 1","non évaluée"))
A13: 6eme | B13: G-b | C13: G.PARA | D13: 1 | E13: =COUNTIFS('04_Questions'!$A:$A,$A13,'04_Questions'!$F:$F,$B13,'04_Questions'!$C:$C,"A") | F13: 1 | G13: =COUNTIFS('04_Questions'!$A:$A,$A13,'04_Questions'!$F:$F,$B13,'04_Questions'!$C:$C,"B") | H13: =COUNTIFS('04_Questions'!$A:$A,$A13,'04_Questions'!$F:$F,$B13,'04_Questions'!$C:$C,"C") | I13: =IF(AND(E13=D13,G13=F13),"OK","écart") | J13: =IF(E13>=1,IF(G13+H13>=1,"OK","sans niveau 2"),IF(G13+H13>=1,"sans niveau 1","non évaluée"))
... A57: 3eme | B57: L-d | C57: L.INEQ1 ; L.MISE | D57: 1 | E57: =COUNTIFS('04_Questions'!$A:$A,$A57,'04_Questions'!$F:$F,$B57,'04_Questions'!$C:$C,"A") | F57: 0 | G57: =COUNTIFS('04_Questions'!$A:$A,$A57,'04_Questions'!$F:$F,$B57,'04_Questions'!$C:$C,"B") | H57: =COUNTIFS('04_Questions'!$A:$A,$A57,'04_Questions'!$F:$F,$B57,'04_Questions'!$C:$C,"C") | I57: =IF(AND(E57=D57,G57=F57),"OK","écart") | J57: =IF(E57>=1,IF(G57+H57>=1,"OK","sans niveau 2"),IF(G57+H57>=1,"sans niveau 1","non évaluée"))
A58: 3eme | B58: G-a | C58: G.ABS | D58: 1 | E58: =COUNTIFS('04_Questions'!$A:$A,$A58,'04_Questions'!$F:$F,$B58,'04_Questions'!$C:$C,"A") | F58: 0 | G58: =COUNTIFS('04_Questions'!$A:$A,$A58,'04_Questions'!$F:$F,$B58,'04_Questions'!$C:$C,"B") | H58: =COUNTIFS('04_Questions'!$A:$A,$A58,'04_Questions'!$F:$F,$B58,'04_Questions'!$C:$C,"C") | I58: =IF(AND(E58=D58,G58=F58),"OK","écart") | J58: =IF(E58>=1,IF(G58+H58>=1,"OK","sans niveau 2"),IF(G58+H58>=1,"sans niveau 1","non évaluée")) | K58: Matrice 3ème, arbitrage 3 : G-a évaluée au seul niveau 1 (G1), faute de place en B et en C.
A59: 3eme | B59: G-b | C59: G.REP | D59: 1 | E59: =COUNTIFS('04_Questions'!$A:$A,$A59,'04_Questions'!$F:$F,$B59,'04_Questions'!$C:$C,"A") | F59: 0 | G59: =COUNTIFS('04_Questions'!$A:$A,$A59,'04_Questions'!$F:$F,$B59,'04_Questions'!$C:$C,"B") | H59: =COUNTIFS('04_Questions'!$A:$A,$A59,'04_Questions'!$F:$F,$B59,'04_Questions'!$C:$C,"C") | I59: =IF(AND(E59=D59,G59=F59),"OK","écart") | J59: =IF(E59>=1,IF(G59+H59>=1,"OK","sans niveau 2"),IF(G59+H59>=1,"sans niveau 1","non évaluée"))
A60: 3eme | B60: G-c | C60: G.VEC | D60: 1 | E60: =COUNTIFS('04_Questions'!$A:$A,$A60,'04_Questions'!$F:$F,$B60,'04_Questions'!$C:$C,"A") | F60: 1 | G60: =COUNTIFS('04_Questions'!$A:$A,$A60,'04_Questions'!$F:$F,$B60,'04_Questions'!$C:$C,"B") | H60: =COUNTIFS('04_Questions'!$A:$A,$A60,'04_Questions'!$F:$F,$B60,'04_Questions'!$C:$C,"C") | I60: =IF(AND(E60=D60,G60=F60),"OK","écart") | J60: =IF(E60>=1,IF(G60+H60>=1,"OK","sans niveau 2"),IF(G60+H60>=1,"sans niveau 1","non évaluée"))
A61: 3eme | B61: G-d | C61: G.PROJ | D61: 1 | E61: =COUNTIFS('04_Questions'!$A:$A,$A61,'04_Questions'!$F:$F,$B61,'04_Questions'!$C:$C,"A") | F61: 1 | G61: =COUNTIFS('04_Questions'!$A:$A,$A61,'04_Questions'!$F:$F,$B61,'04_Questions'!$C:$C,"B") | H61: =COUNTIFS('04_Questions'!$A:$A,$A61,'04_Questions'!$F:$F,$B61,'04_Questions'!$C:$C,"C") | I61: =IF(AND(E61=D61,G61=F61),"OK","écart") | J61: =IF(E61>=1,IF(G61+H61>=1,"OK","sans niveau 2"),IF(G61+H61>=1,"sans niveau 1","non évaluée"))
A62: 3eme | B62: G-e | C62: G.TRANS | D62: 1 | E62: =COUNTIFS('04_Questions'!$A:$A,$A62,'04_Questions'!$F:$F,$B62,'04_Questions'!$C:$C,"A") | F62: 0 | G62: =COUNTIFS('04_Questions'!$A:$A,$A62,'04_Questions'!$F:$F,$B62,'04_Questions'!$C:$C,"B") | H62: =COUNTIFS('04_Questions'!$A:$A,$A62,'04_Questions'!$F:$F,$B62,'04_Questions'!$C:$C,"C") | I62: =IF(AND(E62=D62,G62=F62),"OK","écart") | J62: =IF(E62>=1,IF(G62+H62>=1,"OK","sans niveau 2"),IF(G62+H62>=1,"sans niveau 1","non évaluée"))
A63: 3eme | B63: G-f | C63: G.POLY | D63: 1 | E63: =COUNTIFS('04_Questions'!$A:$A,$A63,'04_Questions'!$F:$F,$B63,'04_Questions'!$C:$C,"A") | F63: 0 | G63: =COUNTIFS('04_Questions'!$A:$A,$A63,'04_Questions'!$F:$F,$B63,'04_Questions'!$C:$C,"B") | H63: =COUNTIFS('04_Questions'!$A:$A,$A63,'04_Questions'!$F:$F,$B63,'04_Questions'!$C:$C,"C") | I63: =IF(AND(E63=D63,G63=F63),"OK","écart") | J63: =IF(E63>=1,IF(G63+H63>=1,"OK","sans niveau 2"),IF(G63+H63>=1,"sans niveau 1","non évaluée"))
A64: 3eme | B64: F-a | C64: F.APP | D64: 0 | E64: =COUNTIFS('04_Questions'!$A:$A,$A64,'04_Questions'!$F:$F,$B64,'04_Questions'!$C:$C,"A") | F64: 1 | G64: =COUNTIFS('04_Questions'!$A:$A,$A64,'04_Questions'!$F:$F,$B64,'04_Questions'!$C:$C,"B") | H64: =COUNTIFS('04_Questions'!$A:$A,$A64,'04_Questions'!$F:$F,$B64,'04_Questions'!$C:$C,"C") | I64: =IF(AND(E64=D64,G64=F64),"OK","écart") | J64: =IF(E64>=1,IF(G64+H64>=1,"OK","sans niveau 2"),IF(G64+H64>=1,"sans niveau 1","non évaluée")) | K64: Matrice 3ème : 17 compétences pour 16 places en partie A ; F-a évaluée aux niveaux 2 (F1) et 3 (P3).
A65: 3eme | B65: D-a | C65: D.STAT1 | D65: 1 | E65: =COUNTIFS('04_Questions'!$A:$A,$A65,'04_Questions'!$F:$F,$B65,'04_Questions'!$C:$C,"A") | F65: 1 | G65: =COUNTIFS('04_Questions'!$A:$A,$A65,'04_Questions'!$F:$F,$B65,'04_Questions'!$C:$C,"B") | H65: =COUNTIFS('04_Questions'!$A:$A,$A65,'04_Questions'!$F:$F,$B65,'04_Questions'!$C:$C,"C") | I65: =IF(AND(E65=D65,G65=F65),"OK","écart") | J65: =IF(E65>=1,IF(G65+H65>=1,"OK","sans niveau 2"),IF(G65+H65>=1,"sans niveau 1","non évaluée"))
A66: 3eme | B66: D-b | C66: D.PROP ; D.POUR ; M.ECH | D66: 1 | E66: =COUNTIFS('04_Questions'!$A:$A,$A66,'04_Questions'!$F:$F,$B66,'04_Questions'!$C:$C,"A") | F66: 1 | G66: =COUNTIFS('04_Questions'!$A:$A,$A66,'04_Questions'!$F:$F,$B66,'04_Questions'!$C:$C,"B") | H66: =COUNTIFS('04_Questions'!$A:$A,$A66,'04_Questions'!$F:$F,$B66,'04_Questions'!$C:$C,"C") | I66: =IF(AND(E66=D66,G66=F66),"OK","écart") | J66: =IF(E66>=1,IF(G66+H66>=1,"OK","sans niveau 2"),IF(G66+H66>=1,"sans niveau 1","non évaluée"))
A67: 2ndeC | B67: N-a | C67: N.RAT ; N.PRIO | D67: 1 | E67: =COUNTIFS('04_Questions'!$A:$A,$A67,'04_Questions'!$F:$F,$B67,'04_Questions'!$C:$C,"A") | F67: 0 | G67: =COUNTIFS('04_Questions'!$A:$A,$A67,'04_Questions'!$F:$F,$B67,'04_Questions'!$C:$C,"B") | H67: =COUNTIFS('04_Questions'!$A:$A,$A67,'04_Questions'!$F:$F,$B67,'04_Questions'!$C:$C,"C") | I67: =IF(AND(E67=D67,G67=F67),"OK","écart") | J67: =IF(E67>=1,IF(G67+H67>=1,"OK","sans niveau 2"),IF(G67+H67>=1,"sans niveau 1","non évaluée"))
A68: 2ndeC | B68: N-b | C68: N.PUI ; N.SCI | D68: 1 | E68: =COUNTIFS('04_Questions'!$A:$A,$A68,'04_Questions'!$F:$F,$B68,'04_Questions'!$C:$C,"A") | F68: 0 | G68: =COUNTIFS('04_Questions'!$A:$A,$A68,'04_Questions'!$F:$F,$B68,'04_Questions'!$C:$C,"B") | H68: =COUNTIFS('04_Questions'!$A:$A,$A68,'04_Questions'!$F:$F,$B68,'04_Questions'!$C:$C,"C") | I68: =IF(AND(E68=D68,G68=F68),"OK","écart") | J68: =IF(E68>=1,IF(G68+H68>=1,"OK","sans niveau 2"),IF(G68+H68>=1,"sans niveau 1","non évaluée"))
A69: 2ndeC | B69: N-c | C69: N.RAC | D69: 2 | E69: =COUNTIFS('04_Questions'!$A:$A,$A69,'04_Questions'!$F:$F,$B69,'04_Questions'!$C:$C,"A") | F69: 1 | G69: =COUNTIFS('04_Questions'!$A:$A,$A69,'04_Questions'!$F:$F,$B69,'04_Questions'!$C:$C,"B") | H69: =COUNTIFS('04_Questions'!$A:$A,$A69,'04_Questions'!$F:$F,$B69,'04_Questions'!$C:$C,"C") | I69: =IF(AND(E69=D69,G69=F69),"OK","écart") | J69: =IF(E69>=1,IF(G69+H69>=1,"OK","sans niveau 2"),IF(G69+H69>=1,"sans niveau 1","non évaluée"))
A70: 2ndeC | B70: N-d | C70: N.INT | D70: 1 | E70: =COUNTIFS('04_Questions'!$A:$A,$A70,'04_Questions'!$F:$F,$B70,'04_Questions'!$C:$C,"A") | F70: 1 | G70: =COUNTIFS('04_Questions'!$A:$A,$A70,'04_Questions'!$F:$F,$B70,'04_Questions'!$C:$C,"B") | H70: =COUNTIFS('04_Questions'!$A:$A,$A70,'04_Questions'!$F:$F,$B70,'04_Questions'!$C:$C,"C") | I70: =IF(AND(E70=D70,G70=F70),"OK","écart") | J70: =IF(E70>=1,IF(G70+H70>=1,"OK","sans niveau 2"),IF(G70+H70>=1,"sans niveau 1","non évaluée"))
A71: 2ndeC | B71: L-a | C71: L.DEV1 ; L.IDR | D71: 2 | E71: =COUNTIFS('04_Questions'!$A:$A,$A71,'04_Questions'!$F:$F,$B71,'04_Questions'!$C:$C,"A") | F71: 1 | G71: =COUNTIFS('04_Questions'!$A:$A,$A71,'04_Questions'!$F:$F,$B71,'04_Questions'!$C:$C,"B") | H71: =COUNTIFS('04_Questions'!$A:$A,$A71,'04_Questions'!$F:$F,$B71,'04_Questions'!$C:$C,"C") | I71: =IF(AND(E71=D71,G71=F71),"OK","écart") | J71: =IF(E71>=1,IF(G71+H71>=1,"OK","sans niveau 2"),IF(G71+H71>=1,"sans niveau 1","non évaluée"))
A72: 2ndeC | B72: L-b | C72: L.FAC1 ; L.FAC2 | D72: 1 | E72: =COUNTIFS('04_Questions'!$A:$A,$A72,'04_Questions'!$F:$F,$B72,'04_Questions'!$C:$C,"A") | F72: 1 | G72: =COUNTIFS('04_Questions'!$A:$A,$A72,'04_Questions'!$F:$F,$B72,'04_Questions'!$C:$C,"B") | H72: =COUNTIFS('04_Questions'!$A:$A,$A72,'04_Questions'!$F:$F,$B72,'04_Questions'!$C:$C,"C") | I72: =IF(AND(E72=D72,G72=F72),"OK","écart") | J72: =IF(E72>=1,IF(G72+H72>=1,"OK","sans niveau 2"),IF(G72+H72>=1,"sans niveau 1","non évaluée"))
A73: 2ndeC | B73: L-c | C73: L.EQ1 ; L.EQP | D73: 2 | E73: =COUNTIFS('04_Questions'!$A:$A,$A73,'04_Questions'!$F:$F,$B73,'04_Questions'!$C:$C,"A") | F73: 1 | G73: =COUNTIFS('04_Questions'!$A:$A,$A73,'04_Questions'!$F:$F,$B73,'04_Questions'!$C:$C,"B") | H73: =COUNTIFS('04_Questions'!$A:$A,$A73,'04_Questions'!$F:$F,$B73,'04_Questions'!$C:$C,"C") | I73: =IF(AND(E73=D73,G73=F73),"OK","écart") | J73: =IF(E73>=1,IF(G73+H73>=1,"OK","sans niveau 2"),IF(G73+H73>=1,"sans niveau 1","non évaluée"))
A74: 2ndeC | B74: L-d | C74: L.INEQ1 | D74: 1 | E74: =COUNTIFS('04_Questions'!$A:$A,$A74,'04_Questions'!$F:$F,$B74,'04_Questions'!$C:$C,"A") | F74: 1 | G74: =COUNTIFS('04_Questions'!$A:$A,$A74,'04_Questions'!$F:$F,$B74,'04_Questions'!$C:$C,"B") | H74: =COUNTIFS('04_Questions'!$A:$A,$A74,'04_Questions'!$F:$F,$B74,'04_Questions'!$C:$C,"C") | I74: =IF(AND(E74=D74,G74=F74),"OK","écart") | J74: =IF(E74>=1,IF(G74+H74>=1,"OK","sans niveau 2"),IF(G74+H74>=1,"sans niveau 1","non évaluée"))
A75: 2ndeC | B75: L-e | C75: L.SYS | D75: 1 | E75: =COUNTIFS('04_Questions'!$A:$A,$A75,'04_Questions'!$F:$F,$B75,'04_Questions'!$C:$C,"A") | F75: 1 | G75: =COUNTIFS('04_Questions'!$A:$A,$A75,'04_Questions'!$F:$F,$B75,'04_Questions'!$C:$C,"B") | H75: =COUNTIFS('04_Questions'!$A:$A,$A75,'04_Questions'!$F:$F,$B75,'04_Questions'!$C:$C,"C") | I75: =IF(AND(E75=D75,G75=F75),"OK","écart") | J75: =IF(E75>=1,IF(G75+H75>=1,"OK","sans niveau 2"),IF(G75+H75>=1,"sans niveau 1","non évaluée"))
A76: 2ndeC | B76: G-a | C76: G.VEC ; G.COL | D76: 2 | E76: =COUNTIFS('04_Questions'!$A:$A,$A76,'04_Questions'!$F:$F,$B76,'04_Questions'!$C:$C,"A") | F76: 1 | G76: =COUNTIFS('04_Questions'!$A:$A,$A76,'04_Questions'!$F:$F,$B76,'04_Questions'!$C:$C,"B") | H76: =COUNTIFS('04_Questions'!$A:$A,$A76,'04_Questions'!$F:$F,$B76,'04_Questions'!$C:$C,"C") | I76: =IF(AND(E76=D76,G76=F76),"OK","écart") | J76: =IF(E76>=1,IF(G76+H76>=1,"OK","sans niveau 2"),IF(G76+H76>=1,"sans niveau 1","non évaluée"))
... A117: tleD | B117: G-b | C117: G.ESP | D117: 1 | E117: =COUNTIFS('04_Questions'!$A:$A,$A117,'04_Questions'!$F:$F,$B117,'04_Questions'!$C:$C,"A") | F117: 1 | G117: =COUNTIFS('04_Questions'!$A:$A,$A117,'04_Questions'!$F:$F,$B117,'04_Questions'!$C:$C,"B") | H117: =COUNTIFS('04_Questions'!$A:$A,$A117,'04_Questions'!$F:$F,$B117,'04_Questions'!$C:$C,"C") | I117: =IF(AND(E117=D117,G117=F117),"OK","écart") | J117: =IF(E117>=1,IF(G117+H117>=1,"OK","sans niveau 2"),IF(G117+H117>=1,"sans niveau 1","non évaluée"))
A119: Contrôle par test
A120: Niveau du test | B120: Questions en A | C120: Questions en B | D120: Sous-questions en C | E120: Barème total | F120: Barème attendu | G120: Contrôle barème | H120: Compétences distinctes en C (principales) | I120: Seuil de la SPEC | J120: Contrôle couverture C
A121: 6eme | B121: =COUNTIFS('04_Questions'!$A:$A,$A121,'04_Questions'!$C:$C,"A") | C121: =COUNTIFS('04_Questions'!$A:$A,$A121,'04_Questions'!$C:$C,"B") | D121: =COUNTIFS('04_Questions'!$A:$A,$A121,'04_Questions'!$C:$C,"C") | E121: =SUMIFS('04_Questions'!$D:$D,'04_Questions'!$A:$A,$A121) | F121: 60 | G121: =IF(E121=F121,"OK","écart") | H121: =SUMPRODUCT(($A$2:$A$117=$A121)*($H$2:$H$117>0)) | I121: 7 | J121: =IF(H121>=I121,"OK","sous le seuil")
A122: 5eme | B122: =COUNTIFS('04_Questions'!$A:$A,$A122,'04_Questions'!$C:$C,"A") | C122: =COUNTIFS('04_Questions'!$A:$A,$A122,'04_Questions'!$C:$C,"B") | D122: =COUNTIFS('04_Questions'!$A:$A,$A122,'04_Questions'!$C:$C,"C") | E122: =SUMIFS('04_Questions'!$D:$D,'04_Questions'!$A:$A,$A122) | F122: 60 | G122: =IF(E122=F122,"OK","écart") | H122: =SUMPRODUCT(($A$2:$A$117=$A122)*($H$2:$H$117>0)) | I122: 7 | J122: =IF(H122>=I122,"OK","sous le seuil")
A123: 4eme | B123: =COUNTIFS('04_Questions'!$A:$A,$A123,'04_Questions'!$C:$C,"A") | C123: =COUNTIFS('04_Questions'!$A:$A,$A123,'04_Questions'!$C:$C,"B") | D123: =COUNTIFS('04_Questions'!$A:$A,$A123,'04_Questions'!$C:$C,"C") | E123: =SUMIFS('04_Questions'!$D:$D,'04_Questions'!$A:$A,$A123) | F123: 60 | G123: =IF(E123=F123,"OK","écart") | H123: =SUMPRODUCT(($A$2:$A$117=$A123)*($H$2:$H$117>0)) | I123: 7 | J123: =IF(H123>=I123,"OK","sous le seuil")
A124: 3eme | B124: =COUNTIFS('04_Questions'!$A:$A,$A124,'04_Questions'!$C:$C,"A") | C124: =COUNTIFS('04_Questions'!$A:$A,$A124,'04_Questions'!$C:$C,"B") | D124: =COUNTIFS('04_Questions'!$A:$A,$A124,'04_Questions'!$C:$C,"C") | E124: =SUMIFS('04_Questions'!$D:$D,'04_Questions'!$A:$A,$A124) | F124: 60 | G124: =IF(E124=F124,"OK","écart") | H124: =SUMPRODUCT(($A$2:$A$117=$A124)*($H$2:$H$117>0)) | I124: 7 | J124: =IF(H124>=I124,"OK","sous le seuil")
...

Sheet 08_Cout_remediation
A1: Competence | B1: Libelle | C1: Volume horaire officiel | D1: Type d'erreur | E1: Libelle du type | F1: Coefficient | G1: Cout estime de remediation (h) | H1: Derivation du volume
A2: N.NUM | B2: Numeration decimale | C2: 2 | D2: PRQ | E2: Prerequis manquant | F2: 0.5 | G2: 1 | H2: 6e ch2 : 2 h / 1 = 2.0 h
A3: N.NUM | B3: Numeration decimale | C3: 2 | D3: CPT | E3: Erreur conceptuelle | F3: 0.35 | G3: 0.5 | H3: 6e ch2 : 2 h / 1 = 2.0 h
A4: N.NUM | B4: Numeration decimale | C4: 2 | D4: MOD | E4: Erreur de modelisation | F4: 0.25 | G4: 0.5 | H4: 6e ch2 : 2 h / 1 = 2.0 h
A5: N.NUM | B5: Numeration decimale | C5: 2 | D5: PRC | E5: Erreur procedurale | F5: 0.15 | G5: 0.5 | H5: 6e ch2 : 2 h / 1 = 2.0 h
A6: N.NUM | B6: Numeration decimale | C6: 2 | D6: CNS | E6: Connaissance non disponible | F6: 0.1 | G6: 0.5 | H6: 6e ch2 : 2 h / 1 = 2.0 h
A7: N.NUM | B7: Numeration decimale | C7: 2 | D7: RED | E7: Defaut de redaction ou de justification | F7: 0.15 | G7: 0.5 | H7: 6e ch2 : 2 h / 1 = 2.0 h
A8: N.CMP | B8: Comparaison et rangement | C8: 3 | D8: PRQ | E8: Prerequis manquant | F8: 0.5 | G8: 1.5 | H8: 6e ch7 : 3 h / 1 = 3.0 h
A9: N.CMP | B9: Comparaison et rangement | C9: 3 | D9: CPT | E9: Erreur conceptuelle | F9: 0.35 | G9: 1 | H9: 6e ch7 : 3 h / 1 = 3.0 h
A10: N.CMP | B10: Comparaison et rangement | C10: 3 | D10: MOD | E10: Erreur de modelisation | F10: 0.25 | G10: 1 | H10: 6e ch7 : 3 h / 1 = 3.0 h
A11: N.CMP | B11: Comparaison et rangement | C11: 3 | D11: PRC | E11: Erreur procedurale | F11: 0.15 | G11: 0.5 | H11: 6e ch7 : 3 h / 1 = 3.0 h
A12: N.CMP | B12: Comparaison et rangement | C12: 3 | D12: CNS | E12: Connaissance non disponible | F12: 0.1 | G12: 0.5 | H12: 6e ch7 : 3 h / 1 = 3.0 h
A13: N.CMP | B13: Comparaison et rangement | C13: 3 | D13: RED | E13: Defaut de redaction ou de justification | F13: 0.15 | G13: 0.5 | H13: 6e ch7 : 3 h / 1 = 3.0 h
... A445: T.TRIR | B445: Trigonometrie dans le triangle rectangle | C445: 6 | D445: RED | E445: Defaut de redaction ou de justification | F445: 0.15 | G445: 1 | H445: 3e ch14 : 6 h / 1 = 6.0 h

Sheet 09_Anomalies
A1: N° | B1: Priorité | C1: Niveau | D1: Document | E1: Elément | F1: Constat | G1: Effet sur le diagnostic | H1: Suite proposée
A2: 1 | B2: 1 | C2: 4ème | D2: Sujet | E2: P2 q1 et P3 q1 | F2: La question 2 redonne la réponse de la question 1 : P2 q2 écrit l'équation 5 000x - 3 000 = 32 000 que P2 q1 demande d'établir, P3 q2 donne les dimensions 45 m sur 30 m que P3 q1 demande de calculer. | G2: Un élève peut recopier la réponse de la question 1 (2 pts chacune) : P2.1 (mise en équation, L.EQD) et P3.1 (échelle, M.ECH) ne mesurent plus la compétence. | H2: Garder l'indépendance des questions 2 et 3 sans donner la réponse : redonner une donnée équivalente mais différente, ou placer la donnée redonnée après un cadre de réponse séparé.
A3: 2 | B3: 1 | C3: 6ème, 3ème, 2nde C, Tle D | D3: Corrigés | E3: Grille de report, partie C | F3: En 3ème, 2nde C et Tle D, le profil par domaine du corrigé rattache chaque problème entier à un seul domaine. En 6ème, la répartition annoncée suppose de couper P1.3 et P3.1 en deux. | G3: Le profil par domaine calculé par l'enseignant sur le corrigé ne sera pas celui que calculera la base à partir de l'onglet 04 (en Tle D : S 12 pts au lieu de 15, T 9 au lieu de 12). Deux lectures différentes d'une même copie. | H3: Aligner la grille (b) de chaque corrigé sur la compétence principale de chaque sous-question de l'onglet 04.
A4: 3 | B4: 1 | C4: 1ère D | D4: Corrigé | E4: P3 q3, barème | F4: Le barème refuse le second point à l'élève qui compare 190 à 204. Or « suffit à coup sûr » équivaut à 190 ≥ 204 : cette comparaison prouve correctement que le grillage ne suffit pas à coup sûr. | G4: Un raisonnement juste est sanctionné et lu comme une erreur sur l'encadrement. | H4: Accepter les deux comparaisons (204 et 196) dans le barème.
A5: 4 | B5: 1 | C5: Tle D | D5: Matrice | E5: P4 q3, conclusion attendue | F5: La matrice attend « Salif a tort » ; le corrigé attend « Salif n'a raison qu'à moitié (isocèle en A, non rectangle) » et refuse le point à qui lui donne entièrement tort. | G5: Selon le document suivi par le correcteur, la même copie gagne ou perd le point de conclusion. | H5: Corriger la matrice sur le corrigé.
A6: 5 | B6: 1 | C6: 2nde C | D6: Corrigé | E6: G11, exemple d'argument | F6: Le corrigé écrit que le dénivelé « double » quand la piste passe de 90 m à 120 m. C'est faux : la longueur est multipliée par 4/3, le dénivelé passe de 45 m à 60 m. | G6: Un correcteur qui suit l'exemple pourrait valider un argument faux. | H6: Corriger la phrase : « il est multiplié par 4/3 ».
A7: 6 | B7: 2 | C7: 4ème | D7: Sujet et matrice | E7: P1 q3 | F7: La matrice dit que les écarts sont redonnés à la question 3 ; le sujet ne les redonne pas. | G7: Un échec en P1.2 se propage à P1.3 (seule la règle d'erreur propagée du corrigé compense). | H7: Redonner les écarts dans l'énoncé de la question 3.
A8: 7 | B8: 2 | C8: 4ème | D8: Sujet et corrigé | E8: P1 | F8: Le sujet dit « à moins de 3 degrés » (strict), le corrigé « 3 degrés au plus » (large). Sans effet ici, aucun écart ne vaut 3. | G8: Aucun aujourd'hui ; risque si les valeurs changent. | H8: Harmoniser la formulation.
A9: 8 | B9: 2 | C9: Tle D | D9: Corrigé | E9: P3 q1, barème | F9: « Un seul des deux points si la hauteur est donnée sans l'heure » : le second point couvre déjà hauteur et heure ensemble, la règle est ambiguë. | G9: Notation variable d'un correcteur à l'autre. | H9: Préciser ce que vaut la hauteur seule.
A10: 9 | B10: 2 | C10: 3ème | D10: Corrigé | E10: P1, donnée inutile (400 m) | F10: Le corrigé dit que l'emploi des 400 m « ne doit pas être compté comme une erreur ». Intégrés au volume (3 600 m³), ils donnent un résultat faux. | G10: Ambiguïté pour le correcteur ; la grille 05 classe ce cas en MOD. | H10: Préciser que seule la simple mention de la donnée n'est pas pénalisée.
A11: 10 | B11: 2 | C11: 1ère D | D11: Sujet | E11: D1 (QCM) | F11: La moyenne des huit masses (49,5) est égale à la médiane. | G11: L'élève qui confond médiane et moyenne entoure la bonne réponse : la confusion est invisible. | H11: Changer une valeur de la série pour séparer moyenne et médiane.
A12: 11 | B12: 2 | C12: 4ème | D12: Sujet | E12: G8 | F12: Avec r = 2 m, 2πr et πr² valent tous deux 12,56. | G12: L'erreur « périmètre au lieu de l'aire du disque » donne la bonne hauteur et reste invisible. | H12: Changer le rayon.
A13: 12 | B13: 2 | C13: Tle D | D13: Sujet | E13: F12 | F13: L'erreur « dérivée de ax² prise égale à ax » donne a = -4, b = 1, puis f'(2) = 5, la bonne valeur. | G13: Le second point ne détecte pas cette erreur ; seul le premier (a = -2) la révèle. | H13: A savoir à la correction ; pas de changement indispensable.
... A28: 27 | B28: 3 | C28: 1ère D | D28: Corrigé | E28: Renvois au livret de remédiation | F28: Les lignes « Si l'élève échoue » de G2, G3, G5, G6, G7, D1, G9, D2 et P2 ne renvoient à aucun module du livret, contrairement aux autres questions. | G28: Aucun sur le tagage. | H28: Vérifier si un module du livret correspond ; n'en citer un que s'il existe.
A30: Priorité 1 : fausse la note ou le diagnostic, à corriger avant la prochaine passation. Priorité 2 : à corriger à la prochaine révision. Priorité 3 : explication ou forme.
